<?xml version="1.0" ?>
<sdf version="1.4">

  
  <gazebo>
    <plugin name="gazebo_ros_control" filename="libgazebo_ros_control.so">
       <robotNamespace>/mybot</robotNamespace>
    </plugin>
  <gazebo>
  
=======
  <-- from http://answers.ros.org/question/9491/how-can-i-simulate-ackermann-steering-in-gazebo/ -->
>>>>>>> master
  <model name='ackermann'>
      <pose>0 0 5 0 -0 0</pose>
      <link name='base'>
      <pose>0 0 0 0 -0 0</pose>
      <inertial>
        <pose>0 0 0 0 -0 0</pose>
        <mass>1</mass>
        <inertia>
          <ixx>1</ixx>
          <ixy>0</ixy>
          <ixz>0</ixz>
          <iyy>1</iyy>
          <iyz>0</iyz>
          <izz>1</izz>
        </inertia>
      </inertial>
      <collision name='base_collision'>
        <pose>0 0 0 0 -0 0</pose>
        <geometry>
          <box>
            <size>2 1 0.1</size>
          </box>
        </geometry>
        <surface>
          <contact>
            <ode/>
          </contact>
          <friction>
            <ode/>
          </friction>
        </surface>
      </collision>
      <visual name='base_visual'>
        <pose>0 0 0 0 -0 0</pose>
        <geometry>
          <box>
            <size>2 1 0.1</size>
          </box>
        </geometry>
        <material>
          <script>
            <name>Gazebo/Blue</name>
            <uri>__default__</uri>
          </script>
        </material>
      </visual>
      <gravity>1</gravity>
      <velocity_decay>
        <linear>0</linear>
        <angular>0</angular>
      </velocity_decay>
      <self_collide>0</self_collide>
    </link>
    <link name='front_left_bar'>
      <pose>1 0.5 0.055 0 -0 0</pose>
      <inertial>
        <pose>0 0 0 0 -0 0</pose>
        <mass>1</mass>
        <inertia>
          <ixx>1</ixx>
          <ixy>0</ixy>
          <ixz>0</ixz>
          <iyy>1</iyy>
          <iyz>0</iyz>
          <izz>1</izz>
        </inertia>
      </inertial>
      <collision name='front_left_bar_collision'>
        <pose>-0.2 -0.2 0 0 -0 0</pose>
        <geometry>
          <box>
            <size>0.4 0.5 0.01</size>
          </box>
        </geometry>
        <surface>
          <contact>
            <ode/>
          </contact>
          <friction>
            <ode/>
          </friction>
        </surface>
      </collision>
      <visual name='front_left_bar_visual'>
        <pose>-0.2 -0.2 0 0 -0 0</pose>
        <geometry>
          <box>
            <size>0.4 0.5 0.01</size>
          </box>
        </geometry>
        <material>
          <script>
            <name>Gazebo/Green</name>
            <uri>__default__</uri>
          </script>
        </material>
      </visual>
      <gravity>1</gravity>
      <velocity_decay>
        <linear>0</linear>
        <angular>0</angular>
      </velocity_decay>
      <self_collide>0</self_collide>
    </link>
    <joint name='front_left_bar_joint' type='revolute'>
      <child>front_left_bar</child>
      <parent>base</parent>
      <axis>
        <xyz>0 0 1</xyz>
        <limit>
          <lower>-0.2</lower>
          <upper>0.2</upper>
          <effort>100</effort>
          <velocity>10</velocity>
        </limit>
        <dynamics/>
      </axis>
    </joint>
    <link name='ackermann_bar'>
      <pose>0.6 0.3 0.105 0 -0 0</pose>
      <inertial>
        <pose>0 0 0 0 -0 0</pose>
        <mass>1</mass>
        <inertia>
          <ixx>1</ixx>
          <ixy>0</ixy>
          <ixz>0</ixz>
          <iyy>1</iyy>
          <iyz>0</iyz>
          <izz>1</izz>
        </inertia>
      </inertial>
      <collision name='ackermann_bar_collision'>
        <pose>-0.05 -0.3 0 0 -0 0</pose>
        <geometry>
          <box>
            <size>0.1 0.6 0.01</size>
          </box>
        </geometry>
        <surface>
          <contact>
            <ode/>
          </contact>
          <friction>
            <ode/>
          </friction>
        </surface>
      </collision>
      <visual name='ackermann_bar_visual'>
        <pose>-0.05 -0.3 0 0 -0 0</pose>
        <geometry>
          <box>
            <size>0.1 0.6 0.01</size>
          </box>
        </geometry>
        <material>
          <script>
            <name>Gazebo/Green</name>
            <uri>__default__</uri>
          </script>
        </material>
      </visual>
      <gravity>1</gravity>
      <velocity_decay>
        <linear>0</linear>
        <angular>0</angular>
      </velocity_decay>
      <self_collide>0</self_collide>
    </link>
    <joint name='ackermann_bar_joint' type='revolute'>
      <child>ackermann_bar</child>
      <parent>front_left_bar</parent>
      <axis>
        <xyz>0 0 1</xyz>
        <limit>
          <lower>-1e+16</lower>
          <upper>1e+16</upper>
        </limit>
        <dynamics/>
      </axis>
    </joint>
    <link name='front_left_wheel'>
      <pose>1 0.6 0.055 0 -0 0</pose>
      <inertial>
        <pose>0 0 0 0 -0 0</pose>
        <mass>1</mass>
        <inertia>
          <ixx>1</ixx>
          <ixy>0</ixy>
          <ixz>0</ixz>
          <iyy>1</iyy>
          <iyz>0</iyz>
          <izz>1</izz>
        </inertia>
      </inertial>
      <collision name='front_left_wheel_collision'>
        <pose>0 0 0 1.5708 -0 0</pose>
        <geometry>
          <cylinder>
            <length>0.01</length>
            <radius>0.2</radius>
          </cylinder>
        </geometry>
        <surface>
          <contact>
            <ode/>
          </contact>
          <friction>
            <ode/>
          </friction>
        </surface>
      </collision>
      <visual name='front_left_wheel_visual'>
        <pose>0 0 0 1.5708 -0 0</pose>
        <geometry>
          <cylinder>
            <length>0.01</length>
            <radius>0.2</radius>
          </cylinder>
        </geometry>
        <material>
          <script>
            <name>Gazebo/Red</name>
            <uri>__default__</uri>
          </script>
        </material>
      </visual>
      <gravity>1</gravity>
      <velocity_decay>
        <linear>0</linear>
        <angular>0</angular>
      </velocity_decay>
      <self_collide>0</self_collide>
    </link>
    <joint name='front_left_wheel_joint' type='revolute'>
      <child>front_left_wheel</child>
      <parent>front_left_bar</parent>
      <axis>
        <xyz>0 1 0</xyz>
        <limit>
          <lower>-1e+16</lower>
          <upper>1e+16</upper>
        </limit>
        <dynamics/>
      </axis>
    </joint>
    <link name='front_right_bar'>
      <pose>1 -0.5 0.055 0 -0 0</pose>
      <inertial>
        <pose>0 0 0 0 -0 0</pose>
        <mass>1</mass>
        <inertia>
          <ixx>1</ixx>
          <ixy>0</ixy>
          <ixz>0</ixz>
          <iyy>1</iyy>
          <iyz>0</iyz>
          <izz>1</izz>
        </inertia>
      </inertial>
      <collision name='front_right_bar_collision'>
        <pose>-0.2 0.2 0 0 -0 0</pose>
        <geometry>
          <box>
            <size>0.4 0.5 0.01</size>
          </box>
        </geometry>
        <surface>
          <contact>
            <ode/>
          </contact>
          <friction>
            <ode/>
          </friction>
        </surface>
      </collision>
      <visual name='front_right_bar_visual'>
        <pose>-0.2 0.2 0 0 -0 0</pose>
        <geometry>
          <box>
            <size>0.4 0.5 0.01</size>
          </box>
        </geometry>
        <material>
          <script>
            <name>Gazebo/Green</name>
            <uri>__default__</uri>
          </script>
        </material>
      </visual>
      <gravity>1</gravity>
      <velocity_decay>
        <linear>0</linear>
        <angular>0</angular>
      </velocity_decay>
      <self_collide>0</self_collide>
    </link>
    <joint name='front_right_bar_joint' type='revolute'>
      <child>front_right_bar</child>
      <parent>base</parent>
      <axis>
        <xyz>0 0 1</xyz>
        <limit>
          <lower>-0.2</lower>
          <upper>0.2</upper>
          <effort>100</effort>
          <velocity>10</velocity>
        </limit>
        <dynamics/>
      </axis>
    </joint>
    <link name='front_right_wheel'>
      <pose>1 -0.6 0.055 0 -0 0</pose>
      <inertial>
        <pose>0 0 0 0 -0 0</pose>
        <mass>1</mass>
        <inertia>
          <ixx>1</ixx>
          <ixy>0</ixy>
          <ixz>0</ixz>
          <iyy>1</iyy>
          <iyz>0</iyz>
          <izz>1</izz>
        </inertia>
      </inertial>
      <collision name='front_right_wheel_collision'>
        <pose>0 0 0 1.5708 -0 0</pose>
        <geometry>
          <cylinder>
            <length>0.01</length>
            <radius>0.2</radius>
          </cylinder>
        </geometry>
        <surface>
          <contact>
            <ode/>
          </contact>
          <friction>
            <ode/>
          </friction>
        </surface>
      </collision>
      <visual name='front_right_wheel_visual'>
        <pose>0 0 0 1.5708 -0 0</pose>
        <geometry>
          <cylinder>
            <length>0.01</length>
            <radius>0.2</radius>
          </cylinder>
        </geometry>
        <material>
          <script>
            <name>Gazebo/Red</name>
            <uri>__default__</uri>
          </script>
        </material>
      </visual>
      <gravity>1</gravity>
      <velocity_decay>
        <linear>0</linear>
        <angular>0</angular>
      </velocity_decay>
      <self_collide>0</self_collide>
    </link>
    <joint name='front_right_wheel_joint' type='revolute'>
      <child>front_right_wheel</child>
      <parent>front_right_bar</parent>
      <axis>
        <xyz>0 1 0</xyz>
        <limit>
          <lower>-1e+16</lower>
          <upper>1e+16</upper>
        </limit>
        <dynamics/>
      </axis>
    </joint>
    <link name='rear_left_wheel'>
      <pose>-1 0.6 0 0 -0 0</pose>
      <inertial>
        <pose>0 0 0 0 -0 0</pose>
        <mass>1</mass>
        <inertia>
          <ixx>1</ixx>
          <ixy>0</ixy>
          <ixz>0</ixz>
          <iyy>1</iyy>
          <iyz>0</iyz>
          <izz>1</izz>
        </inertia>
      </inertial>
      <collision name='rear_left_wheel_collision'>
        <pose>0 0 0 1.5708 -0 0</pose>
        <geometry>
          <cylinder>
            <length>0.01</length>
            <radius>0.2</radius>
          </cylinder>
        </geometry>
        <surface>
          <contact>
            <ode/>
          </contact>
          <friction>
            <ode/>
          </friction>
        </surface>
      </collision>
      <visual name='rear_left_wheel_visual'>
        <pose>0 0 0 1.5708 -0 0</pose>
        <geometry>
          <cylinder>
            <length>0.01</length>
            <radius>0.2</radius>
          </cylinder>
        </geometry>
        <material>
          <script>
            <name>Gazebo/Red</name>
            <uri>__default__</uri>
          </script>
        </material>
      </visual>
      <gravity>1</gravity>
      <velocity_decay>
        <linear>0</linear>
        <angular>0</angular>
      </velocity_decay>
      <self_collide>0</self_collide>
    </link>
    <joint name='rear_left_wheel_joint' type='revolute'>
      <child>rear_left_wheel</child>
      <parent>base</parent>
      <axis>
        <xyz>0 1 0</xyz>
        <limit>
          <lower>-1e+16</lower>
          <upper>1e+16</upper>
        </limit>
        <dynamics/>
      </axis>
    </joint>
    <link name='rear_right_wheel'>
      <pose>-1 -0.6 0 0 -0 0</pose>
      <inertial>
        <pose>0 0 0 0 -0 0</pose>
        <mass>1</mass>
        <inertia>
          <ixx>1</ixx>
          <ixy>0</ixy>
          <ixz>0</ixz>
          <iyy>1</iyy>
          <iyz>0</iyz>
          <izz>1</izz>
        </inertia>
      </inertial>
      <collision name='rear_right_wheel_collision'>
        <pose>0 0 0 1.5708 -0 0</pose>
        <geometry>
          <cylinder>
            <length>0.01</length>
            <radius>0.2</radius>
          </cylinder>
        </geometry>
        <surface>
          <contact>
            <ode/>
          </contact>
          <friction>
            <ode/>
          </friction>
        </surface>
      </collision>
      <visual name='rear_right_wheel_visual'>
        <pose>0 0 0 1.5708 -0 0</pose>
        <geometry>
          <cylinder>
            <length>0.01</length>
            <radius>0.2</radius>
          </cylinder>
        </geometry>
        <material>
          <script>
            <name>Gazebo/Red</name>
            <uri>__default__</uri>
          </script>
        </material>
      </visual>
      <gravity>1</gravity>
      <velocity_decay>
        <linear>0</linear>
        <angular>0</angular>
      </velocity_decay>
      <self_collide>0</self_collide>
    </link>
    <joint name='rear_right_wheel_joint' type='revolute'>
      <child>rear_right_wheel</child>
      <parent>base</parent>
      <axis>
        <xyz>0 1 0</xyz>
        <limit>
          <lower>-1e+16</lower>
          <upper>1e+16</upper>
        </limit>
        <dynamics/>
      </axis>
    </joint>
    <static>0</static>
    <joint name='ackermann_bar_loop_joint' type='revolute'>
      <parent>__default__</parent>
      <child>__default__</child>
      <axis>
        <xyz>0 0 1</xyz>
        <limit>
          <lower>-1e+16</lower>
          <upper>1e+16</upper>
        </limit>
      </axis>
    </joint>
    
      <include>
        <uri>model://hokuyo</uri>
        <pose>0.2 0 0.4 0 0 0</pose>
      </include>
      <joint name="hokuyo_joint" type="revolute">
        <child>hokuyo::link</child>
        <parent>base</parent>
        <axis>
          <xyz>0 0 1</xyz>
          <limit>
            <upper>0</upper>
            <lower>0</lower>
          </limit>
        </axis>
      </joint>
    
    
  </model>
  
    
</sdf>
